Workbook
Name a_allow: Asumsi!$B$47
Name a_avail: Asumsi!$B$7
Name a_buffer: Asumsi!$B$12
Name a_c_admin: Asumsi!$B$38
Name a_c_chp: Asumsi!$B$29
Name a_c_eng_om: Asumsi!$B$34
Name a_c_gfs: Asumsi!$B$28
Name a_c_grid: Asumsi!$B$32
Name a_c_ins: Asumsi!$B$36
Name a_c_levy: Asumsi!$B$25
Name a_c_maint: Asumsi!$B$35
Name a_c_mrv: Asumsi!$B$24
Name a_c_val: Asumsi!$B$23
Name a_cap_kW: Asumsi!$B$9
Name a_carbon_years: Asumsi!$B$22
Name a_cer_ratio: Asumsi!$B$20
Name a_cont: Asumsi!$B$30
Name a_debt_frac: Asumsi!$B$49
Name a_dep_life: Asumsi!$B$46
Name a_diesel_L_tffb: Asumsi!$B$10
Name a_dsra_m: Asumsi!$B$53
Name a_eng: Asumsi!$B$31
Name a_export_on: Asumsi!$B$11
Name a_F_loc: Asumsi!$B$16
Name a_fee_debt: Asumsi!$B$52
Name a_fee_ffb: Asumsi!$B$18
Name a_fx: Asumsi!$B$27
Name a_infl: Asumsi!$B$26
Name a_lease: Asumsi!$B$39
Name a_loss_cf: Asumsi!$B$48
Name a_MCF_eff: Asumsi!$B$21
Name a_n_op: Asumsi!$B$5
Name a_overhaul: Asumsi!$B$43
Name a_p_ac: Asumsi!$B$41
Name a_p_captive: Asumsi!$B$14
Name a_p_carbon: Asumsi!$B$19
Name a_p_naoh: Asumsi!$B$42
Name a_p_poly: Asumsi!$B$40
Name a_pay_days: Asumsi!$B$56
Name a_r_debt: Asumsi!$B$50
Name a_r_eq: Asumsi!$B$54
Name a_ramp1: Asumsi!$B$8
Name a_rec_days: Asumsi!$B$55
Name a_roof_repl: Asumsi!$B$44
Name a_sfc: Asumsi!$B$13
Name a_staff: Asumsi!$B$37
Name a_tariff1: Asumsi!$B$15
Name a_tariff2: Asumsi!$B$17
Name a_tax: Asumsi!$B$45
Name a_tenor: Asumsi!$B$51
Name a_util: Asumsi!$B$6
Name a_vat: Asumsi!$B$33
Name a_year0: Asumsi!$B$4
Name ANN: CAPEX!$F$39
Name DEBT: CAPEX!$F$38
Name FCI26: CAPEX!$F$33
Name FCI: CAPEX!$F$34
Name IDC: CAPEX!$F$37
Name K_af: 'Keputusan PKS'!$B$59
Name K_cake: 'Keputusan PKS'!$B$35

Sheet Ringkasan
A1: MODEL KEUANGAN v3 - SET BIOGAS KONTAK TERMOFILIK YANG DAPAT DIPINDAH (1 set PKS 45 t TBS/jam, BOO, segmen bergantung diesel)
A2: Alur: Asumsi -> CAPEX/OPEX -> Arus Kas -> Indikator; Keputusan PKS (PKS vs kolam); Segmen; Pasar; Pesaing; USP; Sumber. Sel kuning = input.
A4: FCI 2027 (USD) | B4: =FCI -> 5854380.9
A5: USD per kWe kotor (2026) | B5: =FCI26/t_P_gross -> 3821.0156
A6: Pendapatan th 3 (USD) | B6: ='Arus Kas'!F17 -> 1336268.2
A7: EBITDA th 3 (USD) | B7: ='Arus Kas'!F20 -> 906951.44
A8: NPV @WACC (USD) | B8: =Indikator!B4 -> 129020.65
A9: IRR proyek | B9: =Indikator!B5 -> 0.10252362
A10: IRR ekuitas | B10: =Indikator!B6 -> 0.10912528
A11: WACC | B11: =WACC -> 0.099192
A12: Payback sejak COD (th) | B12: =Indikator!B8 -> 7.1072884
A13: Payback terdiskonto (th) | B13: =Indikator!B9 -> 18.756288
A14: DSCR minimum | B14: =Indikator!B11 -> 1.3135116
A15: Porsi pendapatan dari jasa POME | B15: =Indikator!B14 -> 0.33616285
A16: Jasa POME impas (USD/t TBS) | B16: =Indikator!B17 -> 1.192218
A17: Peluang NPV > 0 (Monte Carlo) | B17: ='Monte Carlo'!B9 -> 0.35333333
A18: NPV perusahaan (armada) | B18: =Armada!B60 -> -5202355.4
A19: IRR perusahaan | B19: =Armada!B61 -> 0.078779581
A20: PKS: biaya POME status quo (USD/t TBS) | B20: ='Keputusan PKS'!B61 -> 3.1399756
A21: PKS: biaya POME dengan layanan BOO (USD/t TBS) | B21: ='Keputusan PKS'!E61 -> 3.0039508
A22: PKS hemat vs kolam (%) | B22: ='Keputusan PKS'!E63 -> 0.043320336
A23: Jendela fee (min - maks USD/t TBS) | B23: 1.19 - 1.39

Sheet Asumsi
A1: ASUMSI MODEL v3 (sel kuning = input; seluruh model ikut berubah). Sumber [R1]-[R4] = research/*.md
A3: Nama | B3: Nilai | C3: Satuan | D3: Rendah / Tinggi | E3: Sumber / catatan
A4: year0 | B4: 2027 | C4: tahun | E4: Tahun konstruksi (panel GFS + skid dibuat 6 bln, pasang 4 bln); operasi komersial 2028
A5: n_op | B5: 20 | C5: tahun | E5: Umur operasi kontrak BOO
A6: util | B6: 0.75 | C6: - | D6: 0.6 / 0.9 | E6: Throughput TBS rata-rata tahunan / (45 t/jam x 20 jam x 300 hari); kapasitas PKS ~2x produksi CPO (Trase) [R2/R3]
A7: avail | B7: 0.93 | C7: - | D7: 0.88 / 0.97 | E7: Ketersediaan pembangkit (2 genset n-1, penampung gas 2 jam); 90-97% [R4]
A8: ramp1 | B8: 0.7 | C8: - | D8: 0.55 / 0.85 | E8: Faktor produksi tahun operasi 1: start-up termofilik 2-4 bulan [R4]
A9: cap_kW | B9: 1300 | C9: kW | E9: Kapasitas kontrak ekspor PLN di titik serah (tier Perpres 112 <= 1 MW)
A10: diesel_L_tffb | B10: 2 | C10: L/t TBS | D10: 1.0 / 3.0 | E10: Solar yang DAPAT DIGANTIKAN biogas (PKS + emplasmen + bengkel/KCP). Turunan PalmCo (>2,6 juta L, 2023-2025, 2 PKS; 293.000 m3 POME/th) = 1,9 L/t [R6, keyakinan RENDAH]; DSNG 4,8-5,5 L/t (lokasi terpencil); solar PKS saja 0,4-1,5. Wajib diganti log solar 12 bulan PKS mitra (gerbang G0)
A11: export_on | B11: 1 | C11: 0/1 | D11: 0 / 1 | E11: Ekspor ke PLN tersedia (jaringan 20 kV <= 2 km). 0 = PKS terisolasi: kelebihan listrik tidak terjual
A12: buffer | B12: 1 | C12: 0/1 | D12: 0 / 1 | E12: PM-12: tangki ekualisasi POME 24 jam (600 m3 GFS) agar reaktor diumpan pada hari Minggu; menaikkan kecocokan per jam (process/hourly_match.py). Dalam kasus investasi; belum ada di gambar rekayasa acuan (ditambahkan pada FEED)
A13: sfc | B13: 0.3 | C13: L/kWh | D13: 0.28 / 0.42 | E13: Konsumsi spesifik genset diesel [R2]
A14: p_captive | B14: 0.2 | C14: USD/kWh | D14: 0.15 / 0.26 | E14: Tarif jasa energi ke PKS ~45% di bawah biaya listrik diesel PKS (solar Rp 21.000/L terkirim: USD 0,37/kWh) [R2/R6]. Struktur kontrak: PKS pemegang IUPTLS, SPV pemilik-operator dibayar sewa kapasitas + tarif jasa, bukan jual kWh (perlu konfirmasi Ditjen Gatrik)
A15: tariff1 | B15: 9.81 | C15: USc/kWh | D15: 7.44 / 10.18 | E15: Perpres 112/2022 PLTBg kelas 1-3 MW (kapasitas terpasang 1,6 MWe), th 1-10: 9,81 (media) / 9,94 (Lampiran) / 9,29 (sosialisasi ESDM) [R1/R2/R6, keyakinan sedang]. Skenario buruk: excess power 7,44
A16: F_loc | B16: 1 | C16: - | D16: 1.0 / 1.2 | E16: Faktor lokasi F TIDAK diasumsikan (sumber bertentangan: LPEM/R1 menyatakan tidak berlaku untuk biogas; tabel Undip memakai x F) [R6]; peluang 1,10 hanya di sisi atas
A17: tariff2 | B17: 5.89 | C17: USc/kWh | D17: 4.46 / 6.11 | E17: Perpres 112/2022 PLTBg kelas 1-3 MW, th 11 dst (tanpa F) [R1/R2/R6]
A18: fee_ffb | B18: 1.25 | C18: USD/t TBS | D18: 0.75 / 1.75 | E18: Jasa pengolahan POME: dipilih di dalam jendela kesepakatan (fin_mill.py: di atas fee minimum NPV=0 dan DSCR 1,30; di bawah fee maksimum PKS)
A19: p_carbon | B19: 5 | C19: USD/tCO2e | D19: 3.0 / 8.3 | E19: Kredit penghindaran metana 2025 ~USD 5 (puncak 8,3 2024); IDXCarbon ~3,6 [R1]
A20: cer_ratio | B20: 0.95 | C20: - | D20: 0.85 / 1.0 | E20: Rasio penerbitan setelah UF 0,89 di ER (kebocoran, data hilang)
A21: MCF_eff | B21: 0.3 | C21: - | D21: 0.2 / 0.8 | E21: MCF kolam polishing penerima efluen (fakultatif/aerobik) [IPCC 0,2-0,8]
A22: carbon_years | B22: 10 | C22: tahun | E22: Periode kredit tetap 10 th (Verra/GS)
A23: c_val | B23: 35000 | C23: USD | D23: 20000.0 / 60000.0 | E23: PDD + validasi + registrasi Verra USD 3.750 (sekali, th operasi 1) [R1]
A24: c_mrv | B24: 12000 | C24: USD/th | D24: 8000.0 / 25000.0 | E24: Pemantauan + verifikasi VVB ~USD 50k/10 th + staf MRV [R1]
A25: c_levy | B25: 0.23 | C25: USD/t | E25: Pungutan penerbitan Verra [R1]
A26: infl | B26: 0.02 | C26: /th | D26: 0.015 / 0.035 | E26: Eskalasi biaya & harga dalam USD
A27: fx | B27: 17948 | C27: IDR/USD | D27: 17500.0 / 18500.0 | E27: Kurs referensi BI 15 Okt 2026 [R2]
A28: c_gfs | B28: 200 | C28: USD/m3 | D28: 150.0 / 300.0 | E28: Tangki GFS dibaut terpasang (panel, atap membran ganda, insulasi, internal jet). TIDAK ADA harga vendor publik (R6: placeholder 150, rentang 100-250); 200 = asumsi tim, wajib kuotasi CST/ESP/Center Enamel sebelum FID
A29: c_chp | B29: 600 | C29: USD/kWe | D29: 450.0 / 900.0 | E29: Genset biogas kontainer, termasuk gas train dan instalasi; selaras efisiensi listrik 39,3% di neraca proses (mesin kelas Eropa; dealer mesin saja USD 150-360/kW, belum ada kuotasi) [R6]
A30: cont | B30: 0.2 | C30: - | D30: 0.1 / 0.3 | E30: Kontingensi kelas estimasi 4 (AACE 18R-97; akurasi -20%/+40%), produk perdana termofilik; audit mensyaratkan 20-30%
A31: eng | B31: 0.06 | C31: - | D31: 0.05 / 0.12 | E31: Rekayasa & manajemen proyek (desain berulang)
A32: c_grid | B32: 120000 | C32: USD | D32: 80000.0 / 250000.0 | E32: Switchgear 20 kV + meter transaksi + jaringan <= 2 km (USD 28-42k/km) [R3]
A33: vat | B33: 0.11 | C33: - | E33: PPN efektif atas CAPEX (restitusi th operasi 2)
A34: c_eng_om | B34: 0.018 | C34: USD/kWh-kotor | D34: 0.012 / 0.025 | E34: O&M genset kontrak (tanpa overhaul) 0,012-0,025 [R4]
A35: c_maint | B35: 0.02 | C35: -/th x PEC non-genset | D35: 0.015 / 0.03 | E35: Perawatan peralatan proses
A36: c_ins | B36: 0.005 | C36: -/th x FCI | E36: Asuransi all-risk
A37: staff | B37: 82000 | C37: USD/th | D37: 70000.0 / 100000.0 | E37: 10 orang: manajer, lab/K3, 8 operator (4 regu x 2) - 14 bln gaji + BPJS
A38: c_admin | B38: 30000 | C38: USD/th | E38: Administrasi SPV, SCADA jarak jauh, audit
A39: lease | B39: 2 | C39: USD/m2/th | E39: Sewa lahan plot di PKS (dari GA 3D)
A40: p_poly | B40: 4000 | C40: USD/t | E40: Polimer kationik (dosis 8 kg/t DS [R4])
A41: p_ac | B41: 3000 | C41: USD/t | E41: Karbon aktif impregnasi KI (penjaga)
...

Sheet CAPEX
A1: CAPEX 1 set standar 45 t TBS/jam (USD 2026; dieskalasi ke tahun konstruksi)
A3: Kelompok | B3: Item | C3: Jumlah | D3: Satuan | E3: Harga satuan USD | F3: Total USD | G3: Dasar
A4: PEC | B4: Reaktor kontak termofilik: tangki GFS dibaut 980 m³ (atap membran ganda, insulasi, jet) | C4: 3919.6087 | D4: m³ | E4: =a_c_gfs -> 200 | F4: =C4*E4 -> 783921.74 | G4: Biaya per m³ terpasang [ASUMSI, perlu penawaran]
A5: PEC | B5: TK-101 umpan + TK-301 efluen (tangki GFS kecil) | C5: 297.10041 | D5: m³ | E5: =a_c_gfs*1.3 -> 260 | F5: =C5*E5 -> 77246.107 | G5: Tangki kecil +30%/m³
A6: PEC | B6: TK-102 tangki ekualisasi POME 24 jam (GFS 600 m³, opsi PM-12) | C6: =IF(a_buffer>=0.5,713.0409831864013,0) -> 713.04098 | D6: m³ | E6: =a_c_gfs*1.3 -> 260 | F6: =C6*E6 -> 185390.66 | G6: Tangki kecil +30%/m³
A7: PEC | B7: PM-1 skid praolah (saringan, ruang pasir + hidrosiklon 85%, PHE) | C7: 1 | D7: lot | E7: 225796.31 | F7: =C7*E7 -> 225796.31 | G7: [ASUMSI]
A8: PEC | B8: PM-4 skid kontak: degasser vakum + settler lamella 108 m² + pompa resirkulasi | C8: 1 | D8: lot | E8: 185941.53 | F8: =C8*E8 -> 185941.53 | G8: USD 120k + USD 400/m² proyeksi [ASUMSI]
A9: PEC | B9: PM-5 skid dosing NaOH + pompa umpan | C9: 1 | D9: lot | E9: 59420.082 | F9: =C9*E9 -> 59420.082 | G9: [ASUMSI]
A10: PEC | B10: PM-6 BTF + chiller + blower ATEX + karbon penjaga + analis | C10: 1 | D10: lot | E10: 297100.41 | F10: =C10*E10 -> 297100.41 | G10: [ASUMSI]
A11: PEC | B11: PM-7 penampung gas membran ganda 1315 m³ + flare tertutup | C11: 1 | D11: lot | E11: =90*t_gh_m3+50000 -> 168360.22 | F11: =C11*E11 -> 168360.22 | G11: USD 90/m³ + flare USD 50k
A12: PEC | B12: PM-8 genset biogas kontainer 1600 kWe | C12: 1600 | D12: kWe | E12: =a_c_chp -> 600 | F12: =C12*E12 -> 960000 | G12: Riset harga genset
A13: PEC | B13: PM-9 pemulih panas + menara pendingin | C13: 1 | D13: lot | E13: 118840.16 | F13: =C13*E13 -> 118840.16 | G13: [ASUMSI]
A14: PEC | B14: PM-10 screw press + skid lumpur | C14: 1 | D14: lot | E14: 136666.19 | F14: =C14*E14 -> 136666.19 | G14: [ASUMSI]
A15: PEC | B15: Pipe rack + perpipaan antar modul | C15: 1 | D15: lot | E15: 106956.15 | F15: =C15*E15 -> 106956.15 | G15: Model 3D
A16: PEC | B16: Listrik (trafo 1,25 MVA 0,4/20 kV, switchgear, kabel) | C16: 1 | D16: lot | E16: 237680.33 | F16: =C16*E16 -> 237680.33 | G16: [ASUMSI]
A17: PEC | B17: Instrumentasi, PLC/SCADA jarak jauh | C17: 1 | D17: lot | E17: 106956.15 | F17: =C17*E17 -> 106956.15 | G17: [ASUMSI]
A18: LANGSUNG | B18: Sipil: ring beam 4 tangki + pad skid + jalan/drainase | C18: 1 | D18: lot | E18: 242608.2 | F18: =C18*E18 -> 242608.2 | G18: USD 25k/ring beam + USD 120k [ASUMSI]
A19: LANGSUNG | B19: Transportasi kontainer/skid -> Sumatera (23 muatan) | C19: 23 | D19: muatan | E19: 4500 | F19: =C19*E19 -> 103500 | G19: Kontainer 40 ft + truk
A20: LANGSUNG | B20: Ereksi tangki GFS (3 minggu/tangki), pasang skid, komisioning | C20: 1 | D20: lot | E20: 282608.2 | F20: =C20*E20 -> 282608.2 | G20: [ASUMSI]
A21: LANGSUNG | B21: Lokasi: POME 85 °C DN150 (fat pit -> PM-1) | C21: 161 | D21: m | E21: 140.15652 | F21: =C21*E21 -> 22565.2 | G21: Panjang dari model 3D lokasi (site.json)
A22: LANGSUNG | B22: Lokasi: Efluen settler DN150 HDPE (TK-301 -> kolam fakultatif) | C22: 154 | D22: m | E22: 69.837662 | F22: =C22*E22 -> 10755 | G22: Panjang dari model 3D lokasi (site.json)
A23: LANGSUNG | B23: Lokasi: Bypass darurat DN150 (TK-101 -> kolam pendingin) | C23: 64 | D23: m | E23: 70.191406 | F23: =C23*E23 -> 4492.25 | G23: Panjang dari model 3D lokasi (site.json)
A24: LANGSUNG | B24: Lokasi: Saluran udara 20 kV di lokasi (gardu -> jaringan PLN) | C24: 88 | D24: m | E24: 44.744318 | F24: =C24*E24 -> 3937.5 | G24: Panjang dari model 3D lokasi (site.json)
A25: LANGSUNG | B25: Lokasi: Saluran 20 kV ke rumah mesin PKS (+ trafo 20/0,4 kV di PKS) | C25: 256 | D25: m | E25: 110.28125 | F25: =C25*E25 -> 28232 | G25: Panjang dari model 3D lokasi (site.json)
A26: LANGSUNG | B26: Interkoneksi PLN: switchgear 20 kV, meter transaksi, jaringan <= 2 km | C26: 1 | D26: lot | E26: =a_c_grid -> 120000 | F26: =C26*E26 -> 120000 | G26: [R3] USD 28-42k/km
A27: TAK LANGSUNG | B27: Rekayasa & manajemen proyek | C27: =a_eng -> 0.06 | D27: x PEC | E27: =PEC -> 3650276 | F27: =C27*E27 -> 219016.56 | G27: Desain standar berulang
A28: TAK LANGSUNG | B28: Perizinan (UKL-UPL, Persetujuan Teknis, PPA, SLO, IUPTL) | C28: 1 | D28: lot | E28: 50000 | F28: =C28*E28 -> 50000 | G28: [ASUMSI]
A29: TAK LANGSUNG | B29: Start-up: inokulum termofilik, bahan kimia, pelatihan | C29: 1 | D29: lot | E29: 45000 | F29: =C29*E29 -> 45000 | G29: [ASUMSI]
A30: KONTINGENSI | B30: Kontingensi | C30: =a_cont -> 0.2 | D30: x subtotal | E30: =SUM(F4:F29) -> 4782990.9 | F30: =C30*E30 -> 956598.19 | G30: Produk standar
B32: PEC (peralatan terbeli) | F32: =SUM(F4:F17) -> 3650276
B33: FCI 2026 | F33: =SUM(F4:F30) -> 5739589.1
B34: FCI tahun konstruksi (eskalasi) | F34: =FCI26*(1+a_infl)^(a_year0-2026) -> 5854380.9
B35: Aset berwujud (basis tax allowance) | F35: =SUM(F4:F26)*(1+a_cont)*(1+a_infl)^(a_year0-2026) -> 5470024.6
B36: USD per kWe kotor (2026) | F36: =FCI26/t_P_gross -> 3821.0156
B37: Bunga selama konstruksi (IDC) | F37: =a_debt_frac*FCI*a_r_debt*0.5 -> 135821.64
B38: Pinjaman (termasuk IDC) | F38: =a_debt_frac*FCI+IDC -> 3531362.6
B39: Anuitas th 2-10 | F39: =DEBT*a_r_debt/(1-(1+a_r_debt)^-(a_tenor-1)) -> 565299.49
B41: Pembanding [R3]: kolam tertutup 1,8-3,7 juta USD/MWe; tangki CSTR 1,8-3,5 (TSE 2 MW USD 3,6 juta, 2025); biometana ~USD 5,3 juta/PKS.

Sheet OPEX
A1: OPEX tahun penuh (USD 2026, pada beban util x avail) - dieskalasi di Arus Kas
A3: Komponen | B3: USD/th | C3: Jenis | D3: Rumus
A4: Staf operasi (10 orang) | B4: =a_staff -> 82000 | C4: F | D4: a_staff
A5: O&M genset (kontrak) | B5: =a_c_eng_om*t_Eg_year*a_util/t_up*a_avail*1000000 -> 132402.55 | C5: V | D5: a_c_eng_om*t_Eg_year*a_util/t_up*a_avail*1000000
A6: Perawatan peralatan proses | B6: =a_c_maint*(PEC-a_c_chp*t_chp_kWe) -> 53805.521 | C6: F | D6: a_c_maint*(PEC-a_c_chp*t_chp_kWe)
A7: Bahan kimia (polimer, karbon aktif, NaOH) | B7: =t_ffb*a_util*(t_poly*a_p_poly+t_ac*a_p_ac)/1000+t_naoh*t_days/1000*a_p_naoh -> 49200.885 | C7: V | D7: t_ffb*a_util*(t_poly*a_p_poly+t_ac*a_p_ac)/1000+t_naoh*t_days/1000*a_p_naoh
A8: Asuransi | B8: =a_c_ins*FCI26 -> 28697.946 | C8: F | D8: a_c_ins*FCI26
A9: Administrasi & SCADA jarak jauh | B9: =a_c_admin -> 30000 | C9: F | D9: a_c_admin
A10: Sewa lahan plot di PKS | B10: =a_lease*t_plot_m2 -> 8515.4247 | C10: F | D10: a_lease*t_plot_m2
A12: Biaya tetap (F) | B12: =B4+B6+B8+B9+B10 -> 203018.89
A13: Biaya variabel (V) | B13: =B5+B7 -> 181603.43
A15: Biaya karbon (MRV tahunan + validasi sekali) dan sustaining capex dihitung per tahun di Arus Kas.

Sheet Arus Kas
A1: MODEL ARUS KAS PROYEK v3 (USD nominal; negatif = keluar). 1 set 45 t TBS/jam, BOO, segmen S3
A3: Tahun | C3: 2027 | D3: 2028 | E3: 2029 | F3: 2030 | G3: 2031 | H3: 2032 | I3: 2033 | J3: 2034 | K3: 2035 | L3: 2036 | M3: 2037 | N3: 2038 | O3: 2039 | P3: 2040 | Q3: 2041 | R3: 2042 | S3: 2043 | T3: 2044 | U3: 2045 | V3: 2046 | W3: 2047
A4: Tahun operasi ke- | C4: 0 | D4: 1 | E4: 2 | F4: 3 | G4: 4 | H4: 5 | I4: 6 | J4: 7 | K4: 8 | L4: 9 | M4: 10 | N4: 11 | O4: 12 | P4: 13 | Q4: 14 | R4: 15 | S4: 16 | T4: 17 | U4: 18 | V4: 19 | W4: 20
A5: Tahun kalender | C5: 2027 | D5: 2028 | E5: 2029 | F5: 2030 | G5: 2031 | H5: 2032 | I5: 2033 | J5: 2034 | K5: 2035 | L5: 2036 | M5: 2037 | N5: 2038 | O5: 2039 | P5: 2040 | Q5: 2041 | R5: 2042 | S5: 2043 | T5: 2044 | U5: 2045 | V5: 2046 | W5: 2047
A6: Faktor operasi (ramp-up) | C6: =IF(C4=0,0,IF(C4=1,a_ramp1,1)) -> 0 | D6: =IF(D4=0,0,IF(D4=1,a_ramp1,1)) -> 0.7 | E6: =IF(E4=0,0,IF(E4=1,a_ramp1,1)) -> 1 | F6: =IF(F4=0,0,IF(F4=1,a_ramp1,1)) -> 1 | G6: =IF(G4=0,0,IF(G4=1,a_ramp1,1)) -> 1 | H6: =IF(H4=0,0,IF(H4=1,a_ramp1,1)) -> 1 | I6: =IF(I4=0,0,IF(I4=1,a_ramp1,1)) -> 1 | J6: =IF(J4=0,0,IF(J4=1,a_ramp1,1)) -> 1 | ... W6: =IF(W4=0,0,IF(W4=1,a_ramp1,1)) -> 1
A7: Listrik neto (GWh) | C7: =t_E_year*a_util/t_up*a_avail*C6 -> 0 | D7: =t_E_year*a_util/t_up*a_avail*D6 -> 4.5823591 | E7: =t_E_year*a_util/t_up*a_avail*E6 -> 6.5462273 | F7: =t_E_year*a_util/t_up*a_avail*F6 -> 6.5462273 | G7: =t_E_year*a_util/t_up*a_avail*G6 -> 6.5462273 | H7: =t_E_year*a_util/t_up*a_avail*H6 -> 6.5462273 | I7: =t_E_year*a_util/t_up*a_avail*I6 -> 6.5462273 | J7: =t_E_year*a_util/t_up*a_avail*J6 -> 6.5462273 | ... W7: =t_E_year*a_util/t_up*a_avail*W6 -> 6.5462273
A8: ke PKS menggantikan solar (GWh) | C8: =MIN(t_ffb*a_util*a_diesel_L_tffb/a_sfc/1000000*t_match*a_avail*IF(C6>=1,1,C6),C7) -> 0 | D8: =MIN(t_ffb*a_util*a_diesel_L_tffb/a_sfc/1000000*t_match*a_avail*IF(D6>=1,1,D6),D7) -> 1.0856249 | E8: =MIN(t_ffb*a_util*a_diesel_L_tffb/a_sfc/1000000*t_match*a_avail*IF(E6>=1,1,E6),E7) -> 1.5508927 | F8: =MIN(t_ffb*a_util*a_diesel_L_tffb/a_sfc/1000000*t_match*a_avail*IF(F6>=1,1,F6),F7) -> 1.5508927 | G8: =MIN(t_ffb*a_util*a_diesel_L_tffb/a_sfc/1000000*t_match*a_avail*IF(G6>=1,1,G6),G7) -> 1.5508927 | H8: =MIN(t_ffb*a_util*a_diesel_L_tffb/a_sfc/1000000*t_match*a_avail*IF(H6>=1,1,H6),H7) -> 1.5508927 | I8: =MIN(t_ffb*a_util*a_diesel_L_tffb/a_sfc/1000000*t_match*a_avail*IF(I6>=1,1,I6),I7) -> 1.5508927 | J8: =MIN(t_ffb*a_util*a_diesel_L_tffb/a_sfc/1000000*t_match*a_avail*IF(J6>=1,1,J6),J7) -> 1.5508927 | ... W8: =MIN(t_ffb*a_util*a_diesel_L_tffb/a_sfc/1000000*t_match*a_avail*IF(W6>=1,1,W6),W7) -> 1.5508927
A9: ekspor ke PLN (GWh) | C9: =(C7-C8)*t_capf*a_export_on -> 0 | D9: =(D7-D8)*t_capf*a_export_on -> 3.4967342 | E9: =(E7-E8)*t_capf*a_export_on -> 4.9953346 | F9: =(F7-F8)*t_capf*a_export_on -> 4.9953346 | G9: =(G7-G8)*t_capf*a_export_on -> 4.9953346 | H9: =(H7-H8)*t_capf*a_export_on -> 4.9953346 | I9: =(I7-I8)*t_capf*a_export_on -> 4.9953346 | J9: =(J7-J8)*t_capf*a_export_on -> 4.9953346 | ... W9: =(W7-W8)*t_capf*a_export_on -> 4.9953346
A10: Tarif PLN (USD/kWh) | C10: =IF(C4=0,0,IF(C4<=10,a_tariff1*a_F_loc,a_tariff2)/100) -> 0 | D10: =IF(D4=0,0,IF(D4<=10,a_tariff1*a_F_loc,a_tariff2)/100) -> 0.0981 | E10: =IF(E4=0,0,IF(E4<=10,a_tariff1*a_F_loc,a_tariff2)/100) -> 0.0981 | F10: =IF(F4=0,0,IF(F4<=10,a_tariff1*a_F_loc,a_tariff2)/100) -> 0.0981 | G10: =IF(G4=0,0,IF(G4<=10,a_tariff1*a_F_loc,a_tariff2)/100) -> 0.0981 | H10: =IF(H4=0,0,IF(H4<=10,a_tariff1*a_F_loc,a_tariff2)/100) -> 0.0981 | I10: =IF(I4=0,0,IF(I4<=10,a_tariff1*a_F_loc,a_tariff2)/100) -> 0.0981 | J10: =IF(J4=0,0,IF(J4<=10,a_tariff1*a_F_loc,a_tariff2)/100) -> 0.0981 | ... W10: =IF(W4=0,0,IF(W4<=10,a_tariff1*a_F_loc,a_tariff2)/100) -> 0.0589
A11: Harga listrik ke PKS (USD/kWh) | C11: =IF(C4=0,0,a_p_captive*(1+a_infl)^(C5-2026)) -> 0 | D11: =IF(D4=0,0,a_p_captive*(1+a_infl)^(D5-2026)) -> 0.20808 | E11: =IF(E4=0,0,a_p_captive*(1+a_infl)^(E5-2026)) -> 0.2122416 | F11: =IF(F4=0,0,a_p_captive*(1+a_infl)^(F5-2026)) -> 0.21648643 | G11: =IF(G4=0,0,a_p_captive*(1+a_infl)^(G5-2026)) -> 0.22081616 | H11: =IF(H4=0,0,a_p_captive*(1+a_infl)^(H5-2026)) -> 0.22523248 | I11: =IF(I4=0,0,a_p_captive*(1+a_infl)^(I5-2026)) -> 0.22973713 | J11: =IF(J4=0,0,a_p_captive*(1+a_infl)^(J5-2026)) -> 0.23433188 | ... W11: =IF(W4=0,0,a_p_captive*(1+a_infl)^(W5-2026)) -> 0.30313327
A12: Jasa pengolahan POME & kepatuhan | C12: =IF(C4=0,0,t_ffb*a_util*a_fee_ffb*(1+a_infl)^(C5-2026)) -> 0 | D12: =IF(D4=0,0,t_ffb*a_util*a_fee_ffb*(1+a_infl)^(D5-2026)) -> 351135 | E12: =IF(E4=0,0,t_ffb*a_util*a_fee_ffb*(1+a_infl)^(E5-2026)) -> 358157.7 | F12: =IF(F4=0,0,t_ffb*a_util*a_fee_ffb*(1+a_infl)^(F5-2026)) -> 365320.85 | G12: =IF(G4=0,0,t_ffb*a_util*a_fee_ffb*(1+a_infl)^(G5-2026)) -> 372627.27 | H12: =IF(H4=0,0,t_ffb*a_util*a_fee_ffb*(1+a_infl)^(H5-2026)) -> 380079.82 | I12: =IF(I4=0,0,t_ffb*a_util*a_fee_ffb*(1+a_infl)^(I5-2026)) -> 387681.41 | J12: =IF(J4=0,0,t_ffb*a_util*a_fee_ffb*(1+a_infl)^(J5-2026)) -> 395435.04 | ... W12: =IF(W4=0,0,t_ffb*a_util*a_fee_ffb*(1+a_infl)^(W5-2026)) -> 511537.39
A13: Penjualan listrik ke PKS | C13: =C8*1000000*C11 -> 0 | D13: =D8*1000000*D11 -> 225896.82 | E13: =E8*1000000*E11 -> 329163.94 | F13: =F8*1000000*F11 -> 335747.22 | G13: =G8*1000000*G11 -> 342462.16 | H13: =H8*1000000*H11 -> 349311.41 | I13: =I8*1000000*I11 -> 356297.63 | J13: =J8*1000000*J11 -> 363423.59 | ... W13: =W8*1000000*W11 -> 470127.16
A14: Penjualan listrik ke PLN | C14: =C9*1000000*C10 -> 0 | D14: =D9*1000000*D10 -> 343029.63 | E14: =E9*1000000*E10 -> 490042.32 | F14: =F9*1000000*F10 -> 490042.32 | G14: =G9*1000000*G10 -> 490042.32 | H14: =H9*1000000*H10 -> 490042.32 | I14: =I9*1000000*I10 -> 490042.32 | J14: =J9*1000000*J10 -> 490042.32 | ... W14: =W9*1000000*W10 -> 294225.21
A15: Vintage kredit karbon (tCO2e) | C15: =IF(AND(C4>=1,C4<=a_carbon_years),t_ER*a_cer_ratio*C6,0) -> 0 | D15: =IF(AND(D4>=1,D4<=a_carbon_years),t_ER*a_cer_ratio*D6,0) -> 21301.984 | E15: =IF(AND(E4>=1,E4<=a_carbon_years),t_ER*a_cer_ratio*E6,0) -> 30431.406 | F15: =IF(AND(F4>=1,F4<=a_carbon_years),t_ER*a_cer_ratio*F6,0) -> 30431.406 | G15: =IF(AND(G4>=1,G4<=a_carbon_years),t_ER*a_cer_ratio*G6,0) -> 30431.406 | H15: =IF(AND(H4>=1,H4<=a_carbon_years),t_ER*a_cer_ratio*H6,0) -> 30431.406 | I15: =IF(AND(I4>=1,I4<=a_carbon_years),t_ER*a_cer_ratio*I6,0) -> 30431.406 | J15: =IF(AND(J4>=1,J4<=a_carbon_years),t_ER*a_cer_ratio*J6,0) -> 30431.406 | ... W15: =IF(AND(W4>=1,W4<=a_carbon_years),t_ER*a_cer_ratio*W6,0) -> 0
A16: Kredit karbon terjual (lag 1 th, neto pungutan) | C16: 0 | D16: 0 | E16: =D15*(a_p_carbon-a_c_levy) -> 101610.47 | F16: =E15*(a_p_carbon-a_c_levy) -> 145157.81 | G16: =F15*(a_p_carbon-a_c_levy) -> 145157.81 | H16: =G15*(a_p_carbon-a_c_levy) -> 145157.81 | I16: =H15*(a_p_carbon-a_c_levy) -> 145157.81 | J16: =I15*(a_p_carbon-a_c_levy) -> 145157.81 | K16: =J15*(a_p_carbon-a_c_levy) -> 145157.81 | L16: =K15*(a_p_carbon-a_c_levy) -> 145157.81 | ... W16: =V15*(a_p_carbon-a_c_levy) -> 0
A17: TOTAL PENDAPATAN | C17: =C12+C13+C14+C16 -> 0 | D17: =D12+D13+D14+D16 -> 920061.45 | E17: =E12+E13+E14+E16 -> 1278974.4 | F17: =F12+F13+F14+F16 -> 1336268.2 | G17: =G12+G13+G14+G16 -> 1350289.6 | H17: =H12+H13+H14+H16 -> 1364591.4 | I17: =I12+I13+I14+I16 -> 1379179.2 | J17: =J12+J13+J14+J16 -> 1394058.8 | ... W17: =W12+W13+W14+W16 -> 1275889.8
A18: OPEX operasi (dieskalasi) | C18: =IF(C4=0,0,-(OPEX_F+OPEX_V*C7/(t_E_year*a_util/t_up*a_avail))*(1+a_infl)^(C5-2026)) -> 0 | D18: =IF(D4=0,0,-(OPEX_F+OPEX_V*D7/(t_E_year*a_util/t_up*a_avail))*(1+a_infl)^(D5-2026)) -> -343479 | E18: =IF(E4=0,0,-(OPEX_F+OPEX_V*E7/(t_E_year*a_util/t_up*a_avail))*(1+a_infl)^(E5-2026)) -> -408164.29 | F18: =IF(F4=0,0,-(OPEX_F+OPEX_V*F7/(t_E_year*a_util/t_up*a_avail))*(1+a_infl)^(F5-2026)) -> -416327.57 | G18: =IF(G4=0,0,-(OPEX_F+OPEX_V*G7/(t_E_year*a_util/t_up*a_avail))*(1+a_infl)^(G5-2026)) -> -424654.13 | H18: =IF(H4=0,0,-(OPEX_F+OPEX_V*H7/(t_E_year*a_util/t_up*a_avail))*(1+a_infl)^(H5-2026)) -> -433147.21 | I18: =IF(I4=0,0,-(OPEX_F+OPEX_V*I7/(t_E_year*a_util/t_up*a_avail))*(1+a_infl)^(I5-2026)) -> -441810.15 | J18: =IF(J4=0,0,-(OPEX_F+OPEX_V*J7/(t_E_year*a_util/t_up*a_avail))*(1+a_infl)^(J5-2026)) -> -450646.36 | ... W18: =IF(W4=0,0,-(OPEX_F+OPEX_V*W7/(t_E_year*a_util/t_up*a_avail))*(1+a_infl)^(W5-2026)) -> -582959.11
A19: Biaya karbon (MRV + validasi) | C19: =IF(C4=0,0,-(IF(C4<=a_carbon_years+1,a_c_mrv,0)+IF(C4=1,a_c_val,0))*(1+a_infl)^(C5-2026)) -> 0 | D19: =IF(D4=0,0,-(IF(D4<=a_carbon_years+1,a_c_mrv,0)+IF(D4=1,a_c_val,0))*(1+a_infl)^(D5-2026)) -> -48898.8 | E19: =IF(E4=0,0,-(IF(E4<=a_carbon_years+1,a_c_mrv,0)+IF(E4=1,a_c_val,0))*(1+a_infl)^(E5-2026)) -> -12734.496 | F19: =IF(F4=0,0,-(IF(F4<=a_carbon_years+1,a_c_mrv,0)+IF(F4=1,a_c_val,0))*(1+a_infl)^(F5-2026)) -> -12989.186 | G19: =IF(G4=0,0,-(IF(G4<=a_carbon_years+1,a_c_mrv,0)+IF(G4=1,a_c_val,0))*(1+a_infl)^(G5-2026)) -> -13248.97 | H19: =IF(H4=0,0,-(IF(H4<=a_carbon_years+1,a_c_mrv,0)+IF(H4=1,a_c_val,0))*(1+a_infl)^(H5-2026)) -> -13513.949 | I19: =IF(I4=0,0,-(IF(I4<=a_carbon_years+1,a_c_mrv,0)+IF(I4=1,a_c_val,0))*(1+a_infl)^(I5-2026)) -> -13784.228 | J19: =IF(J4=0,0,-(IF(J4<=a_carbon_years+1,a_c_mrv,0)+IF(J4=1,a_c_val,0))*(1+a_infl)^(J5-2026)) -> -14059.913 | ... W19: =IF(W4=0,0,-(IF(W4<=a_carbon_years+1,a_c_mrv,0)+IF(W4=1,a_c_val,0))*(1+a_infl)^(W5-2026)) -> 0
A20: EBITDA | C20: =C17+C18+C19 -> 0 | D20: =D17+D18+D19 -> 527683.64 | E20: =E17+E18+E19 -> 858075.64 | F20: =F17+F18+F19 -> 906951.44 | G20: =G17+G18+G19 -> 912386.47 | H20: =H17+H18+H19 -> 917930.2 | I20: =I17+I18+I19 -> 923584.8 | J20: =J17+J18+J19 -> 929352.49 | ... W20: =W17+W18+W19 -> 692930.65
A21: CAPEX (FCI) | C21: =IF(C4=0,-FCI,0) -> -5854380.9 | D21: =IF(D4=0,-FCI,0) -> 0 | E21: =IF(E4=0,-FCI,0) -> 0 | F21: =IF(F4=0,-FCI,0) -> 0 | G21: =IF(G4=0,-FCI,0) -> 0 | H21: =IF(H4=0,-FCI,0) -> 0 | I21: =IF(I4=0,-FCI,0) -> 0 | J21: =IF(J4=0,-FCI,0) -> 0 | ... W21: =IF(W4=0,-FCI,0) -> 0
A22: Sustaining: overhaul genset (8,16) + atap membran tangki (12) | C22: =-(IF(OR(C4=8,C4=16),a_overhaul*t_chp_kWe,0)+IF(C4=12,a_roof_repl*t_n_vessel,0))*(1+a_infl)^(C5-2026) -> 0 | D22: =-(IF(OR(D4=8,D4=16),a_overhaul*t_chp_kWe,0)+IF(D4=12,a_roof_repl*t_n_vessel,0))*(1+a_infl)^(D5-2026) -> 0 | E22: =-(IF(OR(E4=8,E4=16),a_overhaul*t_chp_kWe,0)+IF(E4=12,a_roof_repl*t_n_vessel,0))*(1+a_infl)^(E5-2026) -> 0 | F22: =-(IF(OR(F4=8,F4=16),a_overhaul*t_chp_kWe,0)+IF(F4=12,a_roof_repl*t_n_vessel,0))*(1+a_infl)^(F5-2026) -> 0 | G22: =-(IF(OR(G4=8,G4=16),a_overhaul*t_chp_kWe,0)+IF(G4=12,a_roof_repl*t_n_vessel,0))*(1+a_infl)^(G5-2026) -> 0 | H22: =-(IF(OR(H4=8,H4=16),a_overhaul*t_chp_kWe,0)+IF(H4=12,a_roof_repl*t_n_vessel,0))*(1+a_infl)^(H5-2026) -> 0 | I22: =-(IF(OR(I4=8,I4=16),a_overhaul*t_chp_kWe,0)+IF(I4=12,a_roof_repl*t_n_vessel,0))*(1+a_infl)^(I5-2026) -> 0 | J22: =-(IF(OR(J4=8,J4=16),a_overhaul*t_chp_kWe,0)+IF(J4=12,a_roof_repl*t_n_vessel,0))*(1+a_infl)^(J5-2026) -> 0 | ... W22: =-(IF(OR(W4=8,W4=16),a_overhaul*t_chp_kWe,0)+IF(W4=12,a_roof_repl*t_n_vessel,0))*(1+a_infl)^(W5-2026) -> 0
A23: PPN CAPEX (bayar th 0, restitusi th 2) | C23: =IF(C4=0,-a_vat*FCI,IF(C4=2,a_vat*FCI,0)) -> -643981.9 | D23: =IF(D4=0,-a_vat*FCI,IF(D4=2,a_vat*FCI,0)) -> 0 | E23: =IF(E4=0,-a_vat*FCI,IF(E4=2,a_vat*FCI,0)) -> 643981.9 | F23: =IF(F4=0,-a_vat*FCI,IF(F4=2,a_vat*FCI,0)) -> 0 | G23: =IF(G4=0,-a_vat*FCI,IF(G4=2,a_vat*FCI,0)) -> 0 | H23: =IF(H4=0,-a_vat*FCI,IF(H4=2,a_vat*FCI,0)) -> 0 | I23: =IF(I4=0,-a_vat*FCI,IF(I4=2,a_vat*FCI,0)) -> 0 | J23: =IF(J4=0,-a_vat*FCI,IF(J4=2,a_vat*FCI,0)) -> 0 | ... W23: =IF(W4=0,-a_vat*FCI,IF(W4=2,a_vat*FCI,0)) -> 0
A24: Modal kerja (piutang - utang usaha) | C24: =C17*a_rec_days/365+(C18+C19)*a_pay_days/365 -> 0 | D24: =D17*a_rec_days/365+(D18+D19)*a_pay_days/365 -> 118992.75 | E24: =E17*a_rec_days/365+(E18+E19)*a_pay_days/365 -> 175647.95 | F24: =F17*a_rec_days/365+(F18+F19)*a_pay_days/365 -> 184374.22 | G24: =G17*a_rec_days/365+(G18+G19)*a_pay_days/365 -> 185973.37 | H24: =H17*a_rec_days/365+(H18+H19)*a_pay_days/365 -> 187604.51 | I24: =I17*a_rec_days/365+(I18+I19)*a_pay_days/365 -> 189268.27 | J24: =J17*a_rec_days/365+(J18+J19)*a_pay_days/365 -> 190965.31 | ... V24: =V17*a_rec_days/365+(V18+V19)*a_pay_days/365 -> 159596.25 | W24: 0
A25: Perubahan modal kerja | C25: =-C24 -> 0 | D25: =-(D24-C24) -> -118992.75 | E25: =-(E24-D24) -> -56655.204 | F25: =-(F24-E24) -> -8726.2664 | G25: =-(G24-F24) -> -1599.1552 | H25: =-(H24-G24) -> -1631.1383 | I25: =-(I24-H24) -> -1663.761 | J25: =-(J24-I24) -> -1697.0362 | K25: =-(K24-J24) -> -1730.977 | ... W25: =-(W24-V24) -> 159596.25
A26: Penyusutan fiskal (FCI+IDC 8 th; sustaining 8 th) | C26: 0 | D26: =IF(D4<=a_dep_life,(FCI+IDC)/a_dep_life,0)-SUM(D22:D22)/8 -> 748775.32 | E26: =IF(E4<=a_dep_life,(FCI+IDC)/a_dep_life,0)-SUM(D22:E22)/8 -> 748775.32 | F26: =IF(F4<=a_dep_life,(FCI+IDC)/a_dep_life,0)-SUM(D22:F22)/8 -> 748775.32 | G26: =IF(G4<=a_dep_life,(FCI+IDC)/a_dep_life,0)-SUM(D22:G22)/8 -> 748775.32 | H26: =IF(H4<=a_dep_life,(FCI+IDC)/a_dep_life,0)-SUM(D22:H22)/8 -> 748775.32 | I26: =IF(I4<=a_dep_life,(FCI+IDC)/a_dep_life,0)-SUM(D22:I22)/8 -> 748775.32 | J26: =IF(J4<=a_dep_life,(FCI+IDC)/a_dep_life,0)-SUM(D22:J22)/8 -> 748775.32 | K26: =IF(K4<=a_dep_life,(FCI+IDC)/a_dep_life,0)-SUM(D22:K22)/8 -> 784628.1 | L26: =IF(L4<=a_dep_life,(FCI+IDC)/a_dep_life,0)-SUM(E22:L22)/8 -> 35852.777 | M26: =IF(M4<=a_dep_life,(FCI+IDC)/a_dep_life,0)-SUM(F22:M22)/8 -> 35852.777 | N26: =IF(N4<=a_dep_life,(FCI+IDC)/a_dep_life,0)-SUM(G22:N22)/8 -> 35852.777 | O26: =IF(O4<=a_dep_life,(FCI+IDC)/a_dep_life,0)-SUM(H22:O22)/8 -> 52022.86 | P26: =IF(P4<=a_dep_life,(FCI+IDC)/a_dep_life,0)-SUM(I22:P22)/8 -> 52022.86 | Q26: =IF(Q4<=a_dep_life,(FCI+IDC)/a_dep_life,0)-SUM(J22:Q22)/8 -> 52022.86 | R26: =IF(R4<=a_dep_life,(FCI+IDC)/a_dep_life,0)-SUM(K22:R22)/8 -> 52022.86 | ... W26: =IF(W4<=a_dep_life,(FCI+IDC)/a_dep_life,0)-SUM(P22:W22)/8 -> 42007.243
A27: Tax allowance (30% aset berwujud / 6 th) | C27: =IF(AND(C4>=1,C4<=6),a_allow*TANG/6,0) -> 0 | D27: =IF(AND(D4>=1,D4<=6),a_allow*TANG/6,0) -> 273501.23 | E27: =IF(AND(E4>=1,E4<=6),a_allow*TANG/6,0) -> 273501.23 | F27: =IF(AND(F4>=1,F4<=6),a_allow*TANG/6,0) -> 273501.23 | G27: =IF(AND(G4>=1,G4<=6),a_allow*TANG/6,0) -> 273501.23 | H27: =IF(AND(H4>=1,H4<=6),a_allow*TANG/6,0) -> 273501.23 | I27: =IF(AND(I4>=1,I4<=6),a_allow*TANG/6,0) -> 273501.23 | J27: =IF(AND(J4>=1,J4<=6),a_allow*TANG/6,0) -> 0 | ... W27: =IF(AND(W4>=1,W4<=6),a_allow*TANG/6,0) -> 0
A28: Laba kena pajak (tanpa utang) | C28: =C20-C26-C27 -> 0 | D28: =D20-D26-D27 -> -494592.91 | E28: =E20-E26-E27 -> -164200.91 | F28: =F20-F26-F27 -> -115325.11 | G28: =G20-G26-G27 -> -109890.08 | H28: =H20-H26-H27 -> -104346.35 | I28: =I20-I26-I27 -> -98691.752 | J28: =J20-J26-J27 -> 180577.17 | ... W28: =W20-W26-W27 -> 650923.4
A29: Akumulasi rugi fiskal | C29: =MAX(0,-C28) -> 0 | D29: =MAX(0,C29-D28) -> 0 | E29: =MAX(0,D29-E28) -> 0 | F29: =MAX(0,E29-F28) -> 0 | G29: =MAX(0,F29-G28) -> 0 | H29: =MAX(0,G29-H28) -> 0 | I29: =MAX(0,H29-I28) -> 0 | J29: =MAX(0,I29-J28) -> 0 | K29: =MAX(0,J29-K28) -> 0 | ... W29: =MAX(0,V29-W28) -> 0
A30: Pajak (tanpa utang) | C30: =-a_tax*MAX(0,C28) -> 0 | D30: =-a_tax*MAX(0,D28-C29) -> 0 | E30: =-a_tax*MAX(0,E28-D29) -> 0 | F30: =-a_tax*MAX(0,F28-E29) -> 0 | G30: =-a_tax*MAX(0,G28-F29) -> 0 | H30: =-a_tax*MAX(0,H28-G29) -> 0 | I30: =-a_tax*MAX(0,I28-H29) -> 0 | J30: =-a_tax*MAX(0,J28-I29) -> 0 | K30: =-a_tax*MAX(0,K28-J29) -> 0 | ... W30: =-a_tax*MAX(0,W28-V29) -> -143203.15
A31: ARUS KAS BERSIH PROYEK (FCFF) | C31: =C20+C30+C21+C22+C23+C25 -> -6498362.8 | D31: =D20+D30+D21+D22+D23+D25 -> 408690.9 | E31: =E20+E30+E21+E22+E23+E25 -> 1445402.3 | F31: =F20+F30+F21+F22+F23+F25 -> 898225.18 | G31: =G20+G30+G21+G22+G23+G25 -> 910787.31 | H31: =H20+H30+H21+H22+H23+H25 -> 916299.06 | I31: =I20+I30+I21+I22+I23+I25 -> 921921.04 | J31: =J20+J30+J21+J22+J23+J25 -> 927655.45 | ... W31: =W20+W30+W21+W22+W23+W25 -> 709323.74
A32: Kumulatif FCFF | C32: =C31 -> -6498362.8 | D32: =C32+D31 -> -6089671.9 | E32: =D32+E31 -> -4644269.6 | F32: =E32+F31 -> -3746044.4 | G32: =F32+G31 -> -2835257.1 | H32: =G32+H31 -> -1918958 | I32: =H32+I31 -> -997036.99 | J32: =I32+J31 -> -69381.53 | K32: =J32+K31 -> 577300.81 | ... W32: =V32+W31 -> 7319526.7
A33: Faktor diskonto (WACC) | C33: =1/(1+WACC)^0 -> 1 | D33: =1/(1+WACC)^1 -> 0.90975917 | E33: =1/(1+WACC)^2 -> 0.82766174 | F33: =1/(1+WACC)^3 -> 0.75297286 | G33: =1/(1+WACC)^4 -> 0.68502396 | H33: =1/(1+WACC)^5 -> 0.62320683 | I33: =1/(1+WACC)^6 -> 0.56696813 | J33: =1/(1+WACC)^7 -> 0.51580445 | K33: =1/(1+WACC)^8 -> 0.46925783 | L33: =1/(1+WACC)^9 -> 0.42691161 | M33: =1/(1+WACC)^10 -> 0.38838676 | N33: =1/(1+WACC)^11 -> 0.35333841 | O33: =1/(1+WACC)^12 -> 0.32145286 | P33: =1/(1+WACC)^13 -> 0.29244469 | Q33: =1/(1+WACC)^14 -> 0.26605423 | R33: =1/(1+WACC)^15 -> 0.24204528 | S33: =1/(1+WACC)^16 -> 0.22020291 | T33: =1/(1+WACC)^17 -> 0.20033162 | U33: =1/(1+WACC)^18 -> 0.18225353 | V33: =1/(1+WACC)^19 -> 0.16580682 | W33: =1/(1+WACC)^20 -> 0.15084427
A34: FCFF terdiskonto | C34: =C31*C33 -> -6498362.8 | D34: =D31*D33 -> 371810.29 | E34: =E31*E33 -> 1196304.2 | F34: =F31*F33 -> 676339.18 | G34: =G31*G33 -> 623911.14 | H34: =H31*H33 -> 571043.83 | I34: =I31*I33 -> 522699.85 | J34: =J31*J33 -> 478488.82 | ... W34: =W31*W33 -> 106997.42
A35: Kumulatif terdiskonto | C35: =C34 -> -6498362.8 | D35: =C35+D34 -> -6126552.5 | E35: =D35+E34 -> -4930248.3 | F35: =E35+F34 -> -4253909.1 | G35: =F35+G34 -> -3629998 | H35: =G35+H34 -> -3058954.1 | I35: =H35+I34 -> -2536254.3 | J35: =I35+J34 -> -2057765.5 | K35: =J35+K34 -> -1754304.7 | ... W35: =V35+W34 -> 129020.65
A36: Bantu payback (th sejak COD) | C36: ="" -> 0 | D36: =IF(AND(C32<0,D32>=0),0+(-C32/D31),"") -> 0 | E36: =IF(AND(D32<0,E32>=0),1+(-D32/E31),"") -> 0 | F36: =IF(AND(E32<0,F32>=0),2+(-E32/F31),"") -> 0 | G36: =IF(AND(F32<0,G32>=0),3+(-F32/G31),"") -> 0 | H36: =IF(AND(G32<0,H32>=0),4+(-G32/H31),"") -> 0 | I36: =IF(AND(H32<0,I32>=0),5+(-H32/I31),"") -> 0 | J36: =IF(AND(I32<0,J32>=0),6+(-I32/J31),"") -> 0 | K36: =IF(AND(J32<0,K32>=0),7+(-J32/K31),"") -> 0 | L36: =IF(AND(K32<0,L32>=0),8+(-K32/L31),"") -> 0 | M36: =IF(AND(L32<0,M32>=0),9+(-L32/M31),"") -> 0 | N36: =IF(AND(M32<0,N32>=0),10+(-M32/N31),"") -> 0 | O36: =IF(AND(N32<0,O32>=0),11+(-N32/O31),"") -> 0 | P36: =IF(AND(O32<0,P32>=0),12+(-O32/P31),"") -> 0 | Q36: =IF(AND(P32<0,Q32>=0),13+(-P32/Q31),"") -> 0 | R36: =IF(AND(Q32<0,R32>=0),14+(-Q32/R31),"") -> 0 | S36: =IF(AND(R32<0,S32>=0),15+(-R32/S31),"") -> 0 | T36: =IF(AND(S32<0,T32>=0),16+(-S32/T31),"") -> 0 | U36: =IF(AND(T32<0,U32>=0),17+(-T32/U31),"") -> 0 | V36: =IF(AND(U32<0,V32>=0),18+(-U32/V31),"") -> 0 | W36: =IF(AND(V32<0,W32>=0),19+(-V32/W31),"") -> 0
A37: Bantu payback terdiskonto | C37: ="" -> 0 | D37: =IF(AND(C35<0,D35>=0),0+(-C35/D34),"") -> 0 | E37: =IF(AND(D35<0,E35>=0),1+(-D35/E34),"") -> 0 | F37: =IF(AND(E35<0,F35>=0),2+(-E35/F34),"") -> 0 | G37: =IF(AND(F35<0,G35>=0),3+(-F35/G34),"") -> 0 | H37: =IF(AND(G35<0,H35>=0),4+(-G35/H34),"") -> 0 | I37: =IF(AND(H35<0,I35>=0),5+(-H35/I34),"") -> 0 | J37: =IF(AND(I35<0,J35>=0),6+(-I35/J34),"") -> 0 | K37: =IF(AND(J35<0,K35>=0),7+(-J35/K34),"") -> 0 | L37: =IF(AND(K35<0,L35>=0),8+(-K35/L34),"") -> 0 | M37: =IF(AND(L35<0,M35>=0),9+(-L35/M34),"") -> 0 | N37: =IF(AND(M35<0,N35>=0),10+(-M35/N34),"") -> 0 | O37: =IF(AND(N35<0,O35>=0),11+(-N35/O34),"") -> 0 | P37: =IF(AND(O35<0,P35>=0),12+(-O35/P34),"") -> 0 | Q37: =IF(AND(P35<0,Q35>=0),13+(-P35/Q34),"") -> 0 | R37: =IF(AND(Q35<0,R35>=0),14+(-Q35/R34),"") -> 0 | S37: =IF(AND(R35<0,S35>=0),15+(-R35/S34),"") -> 0 | T37: =IF(AND(S35<0,T35>=0),16+(-S35/T34),"") -> 0 | U37: =IF(AND(T35<0,U35>=0),17+(-T35/U34),"") -> 0 | V37: =IF(AND(U35<0,V35>=0),18+(-U35/V34),"") -> 0 | W37: =IF(AND(V35<0,W35>=0),19+(-V35/W34),"") -> 0
A38: Bunga | C38: 0 | D38: =IF(D4<=a_tenor,C40*a_r_debt,0) -> 282509.01 | E38: =IF(E4<=a_tenor,D40*a_r_debt,0) -> 282509.01 | F38: =IF(F4<=a_tenor,E40*a_r_debt,0) -> 259885.77 | G38: =IF(G4<=a_tenor,F40*a_r_debt,0) -> 235452.67 | H38: =IF(H4<=a_tenor,G40*a_r_debt,0) -> 209064.92 | I38: =IF(I4<=a_tenor,H40*a_r_debt,0) -> 180566.16 | J38: =IF(J4<=a_tenor,I40*a_r_debt,0) -> 149787.49 | K38: =IF(K4<=a_tenor,J40*a_r_debt,0) -> 116546.53 | ... W38: =IF(W4<=a_tenor,V40*a_r_debt,0) -> 0
A39: Pokok (tenggang th 1, anuitas th 2-10) | C39: 0 | D39: =IF(AND(D4>=2,D4<=a_tenor),ANN-D38,0) -> 0 | E39: =IF(AND(E4>=2,E4<=a_tenor),ANN-E38,0) -> 282790.49 | F39: =IF(AND(F4>=2,F4<=a_tenor),ANN-F38,0) -> 305413.73 | G39: =IF(AND(G4>=2,G4<=a_tenor),ANN-G38,0) -> 329846.82 | H39: =IF(AND(H4>=2,H4<=a_tenor),ANN-H38,0) -> 356234.57 | I39: =IF(AND(I4>=2,I4<=a_tenor),ANN-I38,0) -> 384733.34 | J39: =IF(AND(J4>=2,J4<=a_tenor),ANN-J38,0) -> 415512 | K39: =IF(AND(K4>=2,K4<=a_tenor),ANN-K38,0) -> 448752.96 | ... W39: =IF(AND(W4>=2,W4<=a_tenor),ANN-W38,0) -> 0
A40: Saldo utang akhir tahun | C40: =DEBT -> 3531362.6 | D40: =C40-D39 -> 3531362.6 | E40: =D40-E39 -> 3248572.1 | F40: =E40-F39 -> 2943158.4 | G40: =F40-G39 -> 2613311.5 | H40: =G40-H39 -> 2257077 | I40: =H40-I39 -> 1872343.6 | J40: =I40-J39 -> 1456831.6 | K40: =J40-K39 -> 1008078.7 | ... W40: =V40-W39 -> 4.0163286e-09
A41: Biaya upfront pinjaman | C41: =-a_fee_debt*DEBT -> -52970.438 | D41: 0 | E41: 0 | F41: 0 | G41: 0 | H41: 0 | I41: 0 | J41: 0 | K41: 0 | L41: 0 | M41: 0 | N41: 0 | O41: 0 | P41: 0 | Q41: 0 | R41: 0 | S41: 0 | T41: 0 | U41: 0 | V41: 0 | W41: 0
...

Sheet Indikator
A1: INDIKATOR KELAYAKAN FINANSIAL v3 (rumus hidup)
A3: Indikator | B3: Hasil | C3: Kriteria | D3: Keputusan
A4: NPV pada WACC (USD) | B4: =SUMPRODUCT('Arus Kas'!$C$31:$W$31,'Arus Kas'!$C$33:$W$33) -> 129020.65 | C4: > 0 | D4: =IF(B4>0,"Layak","Tidak layak") -> 0
A5: IRR proyek (setelah pajak) | B5: =IRR('Arus Kas'!$C$31:$W$31) -> 0.10252362 | C5: > WACC | D5: =IF(B5>WACC,"Layak","Tidak layak") -> 0
A6: IRR ekuitas | B6: =IRR('Arus Kas'!$C$48:$W$48) -> 0.10912528 | C6: > biaya ekuitas | D6: =IF(B6>=a_r_eq-0.0005,"Layak","Tidak layak") -> 0
A7: WACC | B7: =WACC -> 0.099192 | C7: - | D7: ="Informasi" -> 0
A8: Payback sejak COD (th) | B8: =SUM('Arus Kas'!$C$36:$W$36) -> 7.1072884 | C8: < umur | D8: =IF(B8<a_n_op,"Layak","Tidak layak") -> 0
A9: Payback terdiskonto sejak COD (th) | B9: =IF(SUM('Arus Kas'!$C$37:$W$37)=0,"> umur",SUM('Arus Kas'!$C$37:$W$37)) -> 18.756288 | C9: < umur | D9: =IF(ISNUMBER(B9),IF(B9<a_n_op,"Layak","Tidak layak"),"Tidak layak") -> 0
A10: Indeks profitabilitas | B10: =SUMPRODUCT('Arus Kas'!$D$31:$W$31,'Arus Kas'!$D$33:$W$33)/FCI -> 1.1320383 | C10: > 1,0 | D10: =IF(B10>1,"Layak","Tidak layak") -> 0
A11: DSCR minimum | B11: =MIN('Arus Kas'!$C$47:$W$47) -> 1.3135116 | C11: >= 1,3 | D11: =IF(B11>=1.3,"Layak","Tidak layak") -> 0
A12: LCOE kotor (USD/kWh; seluruh biaya ke listrik) | B12: =(FCI-SUMPRODUCT('Arus Kas'!$C$18:$W$18,'Arus Kas'!$C$33:$W$33)-SUMPRODUCT('Arus Kas'!$C$19:$W$19,'Arus Kas'!$C$33:$W$33)-SUMPRODUCT('Arus Kas'!$C$22:$W$22,'Arus Kas'!$C$33:$W$33))/(SUMPRODUCT('Arus Kas'!$C$7:$W$7,'Arus Kas'!$C$33:$W$33)*1000000) -> 0.18606864 | C12: Informasi | D12: ="Informasi" -> 0
A13: Puncak kebutuhan dana (USD) | B13: =-MIN('Arus Kas'!$C$32:$W$32) -> 6498362.8 | C13: Struktur pendanaan | D13: ="Informasi" -> 0
A14: Porsi jasa POME dalam pendapatan | B14: =SUM('Arus Kas'!$C$12:$W$12)/SUM('Arus Kas'!$C$17:$W$17) -> 0.33616285 | C14: Informasi | D14: ="Informasi" -> 0
A16: TITIK IMPAS (dihitung fin_core.bep, bisection NPV = 0)
A17: Jasa POME impas (USD/t TBS) | B17: 1.192218
A18: setara USD/t CPO (OER 21%) | B18: 5.6772285
A19: Tarif PLN th 1-10 impas (USc/kWh, sebelum F) | B19: 9.2859289
A20: Harga karbon impas (USD/t) | B20: 4.0401818
A21: Produksi energi impas (x dasar) | B21: 0.90927918
A22: CAPEX impas (x dasar) | B22: 1.0211158
A23: BEP tunai (fraksi produksi energi) | B23: 0
A24: BEP akuntansi (penyusutan buku) | B24: 0.61152523

Sheet Sensitivitas
A1: SENSITIVITAS NPV (+/-20%)
A3: Variabel | B3: NPV -20% | C3: NPV +20% | D3: Rentang | E3: NPV dasar
A4: Faktor beban PKS | B4: -1399280.6 | C4: 1549605.1 | D4: =ABS(C4-B4) -> 2948885.7 | E4: 129020.65
A5: CAPEX | B5: 1327933.7 | C5: -1109126.5 | D5: =ABS(C5-B5) -> 2437060.2 | E5: 129020.65
A6: OPEX | B6: 761326.81 | C6: -508538.84 | D6: =ABS(C6-B6) -> 1269865.7 | E6: 129020.65
A7: Tarif PLN (x F) | B7: -465439 | C7: 717520.76 | D7: =ABS(C7-B7) -> 1182959.8 | E7: 129020.65
A8: Jasa pengolahan POME (USD/t TBS) | B8: -433416.57 | C8: 686919.11 | D8: =ABS(C8-B8) -> 1120335.7 | E8: 129020.65
A9: Harga listrik ke PKS | B9: -372083.74 | C9: 626220.4 | D9: =ABS(C9-B9) -> 998304.14 | E9: 129020.65
A10: Biaya ekuitas | B10: 658168.03 | C10: -337487.33 | D10: =ABS(C10-B10) -> 995655.36 | E10: 129020.65
A11: Produksi biogas/energi | B11: -180582.15 | C11: 343189.98 | D11: =ABS(C11-B11) -> 523772.14 | E11: 129020.65
A12: Harga karbon | B12: -5454.3669 | C12: 262776.94 | D12: =ABS(C12-B12) -> 268231.31 | E12: 129020.65
A15: PROFIL NPV vs TINGKAT DISKONTO (rumus NPV Excel)
A16: Tingkat diskonto | B16: NPV (USD)
A17: 0.04 | B17: ='Arus Kas'!$C$31+NPV(A17,'Arus Kas'!$D$31:$W$31) -> 3381873.6
A18: 0.045 | B18: ='Arus Kas'!$C$31+NPV(A18,'Arus Kas'!$D$31:$W$31) -> 3015052.7
A19: 0.05 | B19: ='Arus Kas'!$C$31+NPV(A19,'Arus Kas'!$D$31:$W$31) -> 2669457.2
A20: 0.055 | B20: ='Arus Kas'!$C$31+NPV(A20,'Arus Kas'!$D$31:$W$31) -> 2343547.3
A21: 0.06 | B21: ='Arus Kas'!$C$31+NPV(A21,'Arus Kas'!$D$31:$W$31) -> 2035911.6
A22: 0.065 | B22: ='Arus Kas'!$C$31+NPV(A22,'Arus Kas'!$D$31:$W$31) -> 1745255.3
A23: 0.07 | B23: ='Arus Kas'!$C$31+NPV(A23,'Arus Kas'!$D$31:$W$31) -> 1470389.5
A24: 0.075 | B24: ='Arus Kas'!$C$31+NPV(A24,'Arus Kas'!$D$31:$W$31) -> 1210221.6
A25: 0.08 | B25: ='Arus Kas'!$C$31+NPV(A25,'Arus Kas'!$D$31:$W$31) -> 963746.9
A26: 0.085 | B26: ='Arus Kas'!$C$31+NPV(A26,'Arus Kas'!$D$31:$W$31) -> 730040.38
A27: 0.09 | B27: ='Arus Kas'!$C$31+NPV(A27,'Arus Kas'!$D$31:$W$31) -> 508250
A28: 0.095 | B28: ='Arus Kas'!$C$31+NPV(A28,'Arus Kas'!$D$31:$W$31) -> 297590.19
... A57: 0.24 | B57: ='Arus Kas'!$C$31+NPV(A57,'Arus Kas'!$D$31:$W$31) -> -3051109.1
A60: SKENARIO
A61: Skenario | B61: FCI USD | C61: NPV USD | D61: IRR | E61: Payback th
A62: Kasus dasar (60 t/jam + PM-12) | B62: 5854380.9 | C62: 129020.65 | D62: 0.10252362 | E62: 7.1072884
A63: Tanpa tangki ekualisasi | B63: 5613847.7 | C63: 46788.207 | D63: 0.10047526 | E63: 7.0995164
A64: Solar tergantikan 1,0 L/t | B64: 5854380.9 | C64: -663516.95 | D64: 0.080916216 | E64: 8.1882885
A65: Solar tergantikan 3,0 L/t | B65: 5854380.9 | C65: 861968.72 | D65: 0.1203826 | E65: 6.5003501
A66: Tarif excess power 7,44 USc | B66: 5854380.9 | C66: -590639.2 | D66: 0.083751832 | E66: 8.3834414
A67: Faktor lokasi F 1,10 | B67: 5854380.9 | C67: 369291.04 | D67: 0.10878971 | E67: 6.7431128
A68: Karbon USD 8,3/t (puncak 2024) | B68: 5854380.9 | C68: 570416.41 | D68: 0.11392523 | E68: 6.5267628
A69: Tanpa jasa POME | B69: 5854380.9 | C69: -2850683.4 | D69: 0.0064972868 | E69: 18.352865
A70: PKS terisolasi (tanpa ekspor) | B70: 5854380.9 | C70: -3015034.4 | D70: 0.016279297 | E70: 17.149557
A71: Relokasi th-11 | B71: 5854380.9 | C71: 158139.31 | D71: 0.10304657 | E71: 7.1072884
A72: Unit ke-10 (kurva belajar) | B72: 4817059.7 | C72: 1196086.7 | D72: 0.13538019 | E72: 5.8577174
A73: Modul acuan 45 t/jam | B73: 4747903.5 | C73: -545533.66 | D73: 0.08135254 | E73: 8.40446
...

Sheet Monte Carlo
A1: MONTE CARLO (N = 3000). Kasus gagal (tanpa IRR / tidak balik modal) dihitung sebagai nilai terburuk, tidak dibuang.
A3: Statistik | B3: NPV USD | C3: IRR | D3: Payback th
A4: P10 | B4: -1730281.9 | C4: 0.059293482 | D4: 6.3318082
A5: P50 | B5: -388881.76 | C5: 0.090417927 | D5: 7.8448777
A6: P90 | B6: 846751.23 | C6: 0.12045835 | D6: 9.7527643
A7: Rata-rata NPV | B7: -412305.24
A9: Peluang NPV > 0 | B9: 0.35333333
A10: Peluang IRR > WACC | B10: 0.36133333
A11: Kasus tanpa IRR / tidak balik modal | B11: 0 | C11: 0
A13: DISTRIBUSI INPUT (kasus dasar = modus; distribusi condong merugikan)
A14: Input | B14: Spearman ke NPV | D14: Distribusi
A15: util | B15: 0.62443537 | D15: Segitiga 0,60 / 0,75 / 0,90
A16: capex | B16: -0.59799163 | D16: Segitiga 0,90 / 1,00 / 1,35
A17: fee | B17: 0.29111841 | D17: Segitiga 0,75 / 1,00 / 1,25 x dasar
A18: opex | B18: -0.19021361 | D18: Segitiga 0,90 / 1,00 / 1,20
A19: p_carbon | B19: 0.13488161 | D19: Segitiga 3 / 5 / 8,3 USD/t
A20: emult | B20: 0.11700791 | D20: Lognormal median 1, P5-P95 0,85-1,15 (biologi & komposisi POME; util terpisah)
A21: r_debt | B21: -0.10378632 | D21: Segitiga 6,5 / 8 / 10%
A22: F_loc | B22: 0.090860928 | D22: Diskrit 1,00 (30%) / 1,10 (70%)
A23: tier | B23: -0.090541013 | D23: 25%: tarif tawar 90% patokan
A24: avail | B24: 0.060470987 | D24: Segitiga 0,88 / 0,93 / 0,97
A25: ramp1 | B25: 0.038629203 | D25: Segitiga 0,55 / 0,70 / 0,85
A26: infl | B26: 0.02745968 | D26: Segitiga 1,5 / 2 / 3,5%
A27: cer_ratio | B27: 0.023445941 | D27: Segitiga 0,85 / 0,95 / 1,00
A30: Bin NPV (tengah) | B30: Frekuensi
A31: -3719617.4 | B31: 3
A32: -3494195.1 | B32: 2
A33: -3268772.7 | B33: 1
A34: -3043350.3 | B34: 9
A35: -2817928 | B35: 22
A36: -2592505.6 | B36: 22
A37: -2367083.2 | B37: 44
A38: -2141660.8 | B38: 73
A39: -1916238.5 | B39: 89
A40: -1690816.1 | B40: 110
A41: -1465393.7 | B41: 151
A42: -1239971.3 | B42: 185
... A60: 2817631.4 | B60: 1

Sheet Skala Set
A1: EKONOMI PER UKURAN PKS (tangki GFS standar sama: 2 / 3 / 4 tangki)
A3: Indikator | B3: 30 t/jam | C3: 45 t/jam | D3: 60 t/jam
A4: Jumlah tangki reaktor | B4: 2 | C4: 3 | D4: 4
A5: FCI USD | B5: 3582370.6 | C5: 4747903.5 | D5: 5854380.9
A6: Listrik GWh/th (th 2) | B6: 3.257571 | C6: 4.9018991 | D6: 6.5462273
A7: Pendapatan th 2 USD | B7: 647146.35 | C7: 958468.46 | D7: 1278974.4
A8: NPV USD | B8: -1122674.5 | C8: -545533.66 | D8: 129020.65
A9: IRR | B9: 0.048259985 | C9: 0.08135254 | D9: 0.10252362
A10: Payback th | B10: 10.633361 | C10: 8.40446 | D10: 7.1072884
A12: Set 60 t/jam (> 1 MW neto pada hari nameplate) memakai tier Perpres 112 >1-3 MW (9,81 / 5,89 USc).

Sheet Armada
A1: MODEL PERUSAHAAN: 10 set BOO 2027-2034, kurva belajar 90% pada 60% FCI, unit-1 FOAK +20%, CAPEX dieskalasi, overhead tanpa perisai pajak
A3: Tahun | B3: 2026 | C3: 2027 | D3: 2028 | E3: 2029 | F3: 2030 | G3: 2031 | H3: 2032 | I3: 2033 | J3: 2034 | K3: 2035 | L3: 2036 | M3: 2037 | N3: 2038 | O3: 2039 | P3: 2040 | Q3: 2041 | R3: 2042 | S3: 2043 | T3: 2044 | U3: 2045 | V3: 2046 | W3: 2047 | X3: 2048 | Y3: 2049 | Z3: 2050 | AA3: 2051 | AB3: 2052 | AC3: 2053 | AD3: 2054
A4: Set baru | B4: 0 | C4: 1 | D4: 1 | E4: 1 | F4: 1 | G4: 1 | H4: 1 | I4: 2 | J4: 2 | K4: 0 | L4: 0 | M4: 0 | N4: 0 | O4: 0 | P4: 0 | Q4: 0 | R4: 0 | S4: 0 | T4: 0 | U4: 0 | V4: 0 | W4: 0 | X4: 0 | Y4: 0 | Z4: 0 | AA4: 0 | AB4: 0 | AC4: 0 | AD4: 0
A5: Set beroperasi | B5: 0 | C5: 0 | D5: 1 | E5: 2 | F5: 3 | G5: 4 | H5: 5 | I5: 6 | J5: 8 | K5: 10 | L5: 10 | M5: 10 | N5: 10 | O5: 10 | P5: 10 | Q5: 10 | R5: 10 | S5: 10 | T5: 10 | U5: 10 | V5: 10 | W5: 10 | X5: 9 | Y5: 8 | Z5: 7 | AA5: 6 | AB5: 5 | AC5: 4 | AD5: 2
A6: Listrik GWh | B6: 0 | C6: 0 | D6: 4.5823591 | E6: 11.128586 | F6: 17.674814 | G6: 24.221041 | H6: 30.767268 | I6: 37.313495 | J6: 48.442082 | K6: 61.534536 | L6: 65.462273 | M6: 65.462273 | N6: 65.462273 | O6: 65.462273 | P6: 65.462273 | Q6: 65.462273 | R6: 65.462273 | S6: 65.462273 | T6: 65.462273 | U6: 65.462273 | V6: 65.462273 | W6: 65.462273 | X6: 58.916045 | Y6: 52.369818 | Z6: 45.823591 | AA6: 39.277364 | AB6: 32.731136 | AC6: 26.184909 | AD6: 13.092455
A7: Kredit karbon tCO2e | B7: 0 | C7: 0 | D7: 21301.984 | E7: 51733.391 | F7: 82164.797 | G7: 112596.2 | H7: 143027.61 | I7: 173459.02 | J7: 225192.41 | K7: 286055.22 | L7: 304314.06 | M7: 304314.06 | N7: 273882.66 | O7: 243451.25 | P7: 213019.84 | Q7: 182588.44 | R7: 152157.03 | S7: 121725.63 | T7: 60862.813 | U7: 0 | V7: 0 | W7: 0 | X7: 0 | Y7: 0 | Z7: 0 | AA7: 0 | AB7: 0 | AC7: 0 | AD7: 0
A8: Pendapatan USD | B8: 0 | C8: 0 | D8: 920061.45 | E8: 2210576.5 | F8: 3572362.6 | G8: 4962701.8 | H8: 6382445.5 | I8: 7832467.9 | J8: 10306528 | K8: 13198508 | L8: 14160072 | M8: 14405070 | N8: 14370314 | O8: 14193622 | P8: 14020215 | Q8: 13850160 | R8: 13683523 | S8: 13520373 | T8: 13164962 | U8: 12668021 | V8: 12566414 | W8: 12758898 | X8: 11659707 | Y8: 10524392 | Z8: 9351828.4 | AA8: 8140862.9 | AB8: 6890311 | AC8: 5598955.7 | AD8: 2843698.4
A9: jasa POME | B9: 0 | C9: 0 | D9: 351135 | E9: 716315.4 | F9: 1095962.6 | G9: 1490509.1 | H9: 1900399.1 | I9: 2326088.5 | J9: 3163480.3 | K9: 4033437.4 | L9: 4114106.2 | M9: 4196388.3 | N9: 4280316.1 | O9: 4365922.4 | P9: 4453240.8 | Q9: 4542305.6 | R9: 4633151.8 | S9: 4725814.8 | T9: 4820331.1 | U9: 4916737.7 | V9: 5015072.5 | W9: 5115373.9 | X9: 4695913.2 | Y9: 4257628 | Z9: 3799933 | AA9: 3322227.1 | AB9: 2823893.1 | AC9: 2304296.7 | AD9: 1175191.3
A10: listrik | B10: 0 | C10: 0 | D10: 568926.45 | E10: 1392650.6 | F10: 2229631.8 | G10: 3080266.6 | H10: 3944962.5 | I10: 4824137.8 | J10: 6315647.7 | K10: 8090903.2 | L10: 8681482.2 | M10: 8757103.4 | N10: 8638419.9 | O10: 8521279.1 | P10: 8405711.7 | Q10: 8291749.4 | R10: 8179424.2 | S10: 8068768.8 | T10: 7763999.5 | U10: 7460967.6 | V10: 7551341.9 | W10: 7643523.7 | X10: 6963794.2 | Y10: 6266764 | Z10: 5551895.4 | AA10: 4818635.8 | AB10: 4066417.9 | AC10: 3294659 | AD10: 1668507.1
A11: karbon | B11: 0 | C11: 0 | D11: 0 | E11: 101610.47 | F11: 246768.27 | G11: 391926.08 | H11: 537083.89 | I11: 682241.7 | J11: 827399.51 | K11: 1074167.8 | L11: 1364483.4 | M11: 1451578.1 | N11: 1451578.1 | O11: 1306420.3 | P11: 1161262.5 | Q11: 1016104.7 | R11: 870946.85 | S11: 725789.04 | T11: 580631.23 | U11: 290315.62 | V11: 0 | W11: 0 | X11: 0 | Y11: 0 | Z11: 0 | AA11: 0 | AB11: 0 | AC11: 0 | AD11: 0
A12: OPEX USD | B12: 0 | C12: 0 | D12: 413540.26 | E12: 836234.14 | F12: 1272117.1 | G12: 1722661.6 | H12: 2188862.7 | I12: 2671522.6 | J12: 3593857.8 | K12: 4571492.9 | L12: 4710417.3 | M12: 4804625.7 | N12: 4900718.2 | O12: 4983209.3 | P12: 5067039.7 | Q12: 5152230.1 | R12: 5238801.3 | S12: 5326774.4 | T12: 5416170.9 | U12: 5489530.9 | V12: 5563658.8 | W12: 5674931.9 | X12: 5162366 | Y12: 4668725.2 | Z12: 4158553.7 | AA12: 3629732.6 | AB12: 3080853.7 | AC12: 2510796.9 | AD12: 1277733.8
A13: EBITDA USD | B13: 0 | C13: 0 | D13: 506521.19 | E13: 1374342.4 | F13: 2300245.5 | G13: 3240040.1 | H13: 4193582.8 | I13: 5160945.3 | J13: 6712669.8 | K13: 8627015.4 | L13: 9449654.5 | M13: 9600444.1 | N13: 9469595.8 | O13: 9210412.4 | P13: 8953175.3 | Q13: 8697929.6 | R13: 8444721.5 | S13: 8193598.2 | T13: 7748790.9 | U13: 7178490 | V13: 7002755.6 | W13: 7083965.7 | X13: 6497341.5 | Y13: 5855666.8 | Z13: 5193274.6 | AA13: 4511130.3 | AB13: 3809457.2 | AC13: 3088158.8 | AD13: 1565964.6
A14: CAPEX + sustaining USD | B14: 0 | C14: 7025257.1 | D14: 5613180.4 | E14: 5528851.7 | F14: 5504466.2 | G14: 5511846.2 | H14: 5539083.9 | I14: 11101060 | J14: 11112478 | K14: 286822.22 | L14: 292558.66 | M14: 298409.83 | N14: 304378.03 | O14: 439826.25 | P14: 448622.78 | Q14: 780603.64 | R14: 796215.71 | S14: 476082.08 | T14: 485603.72 | U14: 640996.92 | V14: 653816.85 | W14: 363759.92 | X14: 371035.12 | Y14: 756911.65 | Z14: 772049.88 | AA14: 0 | AB14: 0 | AC14: 0 | AD14: 0
... A16: FCFF perusahaan USD | B16: -1050000 | C16: -8279535.4 | D16: -6356567.4 | E16: -4718571.6 | F16: -3970149.7 | G16: -3092601.6 | H16: -2219702.3 | I16: -7476218.7 | J16: -6116951.9 | K16: 8377621.8 | L16: 9428401.2 | M16: 8322475.6 | N16: 7969085.7 | O16: 7270085.7 | P16: 6831520.5 | Q16: 6056486.6 | R16: 5385762.7 | S16: 5130457.4 | T16: 4792535.7 | U16: 4204826 | V16: 3980392.3 | W16: 4426086 | X16: 3937211.7 | Y16: 3025017.9 | Z16: 2466808.2 | AA16: 2676662.8 | AB16: 2098643.2 | AC16: 1679174.8 | AD16: 451001.49
A17: Kumulatif FCFF | B17: =B16 -> 0 | C17: =B17+C16 -> 0 | D17: =C17+D16 -> 0 | E17: =D17+E16 -> 0 | F17: =E17+F16 -> 0 | G17: =F17+G16 -> 0 | H17: =G17+H16 -> 0 | I17: =H17+I16 -> 0 | J17: =I17+J16 -> 0 | ... AD17: =AC17+AD16 -> 0
A19: NPV perusahaan @WACC | B19: =B16+NPV(WACC,C16:AD16) -> -5202355.4
A20: IRR perusahaan | B20: =IRR(B16:AD16) -> 0.078779581
A21: Puncak kebutuhan dana | B21: =-MIN(B17:AD17) -> 43280299
A23: Unit ke- | B23: Tahun | C23: Faktor CAPEX | D23: FCI USD | E23: NPV unit USD | F23: IRR unit
A24: 1 | B24: 2027 | C24: 1.2 | D24: 7025257.1 | E24: -1109126.5 | F24: 0.074554991
A25: 2 | B25: 2028 | C25: 0.94 | D25: 5613180.4 | E25: 433111.7 | F25: 0.11073863
A26: 3 | B26: 2029 | C26: 0.90772359 | D26: 5528851.7 | E26: 574894.67 | F26: 0.11467059
A27: 4 | B27: 2030 | C27: 0.886 | D27: 5504466.2 | E27: 655332.06 | F27: 0.11685487
A28: 5 | B28: 2031 | C28: 0.86979203 | D28: 5511846.2 | E28: 703789.84 | F28: 0.11809069
A29: 6 | B29: 2032 | C29: 0.85695123 | D29: 5539083.9 | E29: 732502.4 | F29: 0.11872994
A30: 7 | B30: 2033 | C30: 0.8463687 | D30: 5580095.1 | E30: 748137.16 | F30: 0.11897333
A31: 8 | B31: 2033 | C31: 0.8374 | D31: 5520964.6 | E31: 808912.1 | F31: 0.12076655
A32: 9 | B32: 2034 | C32: 0.82963874 | D32: 5579190.7 | E32: 808009.01 | F32: 0.12050046
A33: 10 | B33: 2034 | C33: 0.82281283 | D33: 5533287.5 | E33: 855188.8 | F33: 0.12189699

Sheet Lokasi
A1: INTERKONEKSI & LAHAN DARI MODEL 3D LOKASI (cad/out/site.json)
A3: Rute | B3: Panjang m | C3: USD/m | D3: Biaya USD
A4: POME 85 °C DN150 (fat pit -> PM-1) | B4: 161 | C4: 140 | D4: 22565.2
A5: Efluen settler DN150 HDPE (TK-301 -> kolam fakultatif) | B5: 154 | C5: 70 | D5: 10755
A6: Bypass darurat DN150 (TK-101 -> kolam pendingin) | B6: 64 | C6: 70 | D6: 4492.25
A7: Saluran udara 20 kV di lokasi (gardu -> jaringan PLN) | B7: 88 | C7: 45 | D7: 3937.5
A8: Saluran 20 kV ke rumah mesin PKS (+ trafo 20/0,4 kV di PKS) | B8: 256 | C8: 40 | D8: 28232
A11: Luas kolam POME sebelum (m2) | B11: 22361.435
A12: Luas kolam setelah - tetap untuk polishing (m2) | B12: 11280.682
A13: Lahan kolam dibebaskan (m2) | B13: 11080.753
A14: Luas plot produk (m2) | B14: 4257.7123
A17: PEMERIKSAAN JARAK AMAN
A18: Item | B18: Jarak m | C18: Minimum m | D18: OK
A19: Flare FL-301 -> tepi GH-301 (API 537 / praktik biogas) | B19: 15.8 | C19: 15 | D19: Ya
A20: Flare FL-301 -> kontainer CHP (Sumber nyala vs zona gas) | B20: 20.8 | C20: 15 | D20: Ya
A21: GH-301 -> rumah boiler PKS (Sumber nyala terbuka) | B21: 141.5 | C21: 30 | D21: Ya
A22: GH-301 -> tangki CPO (Bahan mudah terbakar) | B22: 208 | C22: 30 | D22: Ya
A23: Flare -> batas pagar lokasi (Radiasi panas di batas) | B23: 21.5 | C23: 10 | D23: Ya
A24: Reaktor -> kolam pendingin (tanah) (Stabilitas lereng / pondasi) | B24: 20.9 | C24: 20 | D24: Ya
A25: Cerobong boiler -> GH-301 (Bunga api cerobong) | B25: 137.1 | C25: 30 | D25: Ya

Sheet Pasar
A1: UKURAN PASAR BOTTOM-UP (sel kuning = input; setara-set = 1 set per PKS / volume POME 1 set)
A3: Parameter | B3: Nilai | C3: Satuan | D3: Keyakinan | E3: Sumber
A4: PKS beroperasi di Indonesia | B4: 1300 | C4: PKS | D4: H | E4: Trase/Universal Mill List 1.318 (2022) [R3]
A5: Porsi sudah menangkap metana | B5: 0.115 | C5: - | D5: M | E5: 84 PLTBg POME ~165 MW (GAPKI 2026) [R3]
A6: POME nasional | B6: 150000000 | C6: m3/th | D6: M | E6: 125-170 juta m3 [R3]
A7: Porsi PKS 30-60 t/jam | B7: 0.65 | C7: - | D7: L | E7: Estimasi kelas kapasitas [R3]; perlu CSV Trase
A8: Porsi Sumatera + Kalimantan | B8: 0.85 | C8: - | D8: M | E8: Sebaran PKS [R3]
A9: Porsi PKS solar terukur >= 2 L/t TBS | B9: 0.2 | C9: - | D9: EST | E9: HIPOTESIS: basis lemah (Kaltim 12/62 desa diesel-saja bukan solar PKS); rentang 0,10-0,35; validasi survei 30 PKS (gerbang G0)
A10: Porsi PKS dengan jaringan 20 kV <= 2 km | B10: 0.6 | C10: - | D10: EST | E10: HIPOTESIS: ekspor layak; rentang 0,40-0,80
A11: Porsi PKS bebas program biogas grup | B11: 0.75 | C11: - | D11: EST | E11: HIPOTESIS: di luar Wilmar, Musim Mas, Asian Agri, dll.; rentang 0,60-0,90
A12: POME per set (m3/th) | B12: 175500 | C12: m3/th | D12: Model | E12: 45 t/jam x 20 x 300 x util x 0,65
A13: Pendapatan rata-rata per set (USD/th) | B13: 1268976.8 | C13: USD/th | D13: Model | E13: Arus Kas, rata-rata 20 th
A14: Set SOM s/d 2034 (rencana armada) | B14: 10 | C14: set | D14: Rencana | E14: ROLL di fin_core
A15: MWe terpasang per set | B15: 1.6 | C15: MWe | D15: Model | E15: 2 x 600 kWe
A18: Tingkat | B18: PKS / set | C18: MWe | D18: Pendapatan USD/th | E18: Aturan
A19: TAM (volume POME semua PKS tanpa penangkap metana) | B19: =B6*(1-B5)/B12 -> 756.41026 | C19: =B19*B15 -> 1210.2564 | D19: =B19*B13 -> 9.5986704e+08 | E19: Semua PKS Indonesia tanpa penangkap metana (volume POME)
A20: SAM-luas (+30-60 t/jam, Sumatera/Kalimantan) | B20: =B4*(1-B5)*B7*B8 -> 635.65125 | C20: =B20*B15 -> 1017.042 | D20: =B20*B13 -> 8.0662667e+08 | E20: + ukuran 30-60 t/jam + Sumatera/Kalimantan
A21: SAM (+bergantung diesel: jendela kesepakatan terbuka) | B21: =B20*B9*B10*B11 -> 57.208613 | C21: =B21*B15 -> 91.53378 | D21: =B21*B13 -> 72596400 | E21: + solar >= 2 L/t TBS + jaringan 20 kV <= 2 km + bebas program grup: jendela kesepakatan terbuka
A22: SOM 2034 | B22: =B14 -> 10 | C22: =B22*B15 -> 16 | D22: =B22*B13 -> 12689768 | E22: Rencana armada (ROLL) - 1 set per PKS
A24: Pangsa SOM / SAM | B24: =B22/B21 -> 0.17479886
A25: SOM vs laju bangun PLTBg nasional (9 MW/th) [R3] | B25: =C22/8/9 -> 0.22222222
A26: Ekspansi: Malaysia ~315 PKS tanpa penangkap metana [R3] -> setara-set segmen diesel | B26: 18.4275
A28: PKS per provinsi (estimasi [R3, L])
A29: Provinsi | B29: PKS | C29: SAM (estimasi)
A30: Riau | B30: 260 | C30: =B30*(1-$B$5)*$B$7*$B$9*$B$10*$B$11 -> 13.46085
A31: Sumut | B31: 180 | C31: =B31*(1-$B$5)*$B$7*$B$9*$B$10*$B$11 -> 9.31905
A32: Kalteng | B32: 130 | C32: =B32*(1-$B$5)*$B$7*$B$9*$B$10*$B$11 -> 6.730425
A33: Kalbar | B33: 120 | C33: =B33*(1-$B$5)*$B$7*$B$9*$B$10*$B$11 -> 6.2127
A34: Sumsel | B34: 110 | C34: =B34*(1-$B$5)*$B$7*$B$9*$B$10*$B$11 -> 5.694975
A35: Kaltim | B35: 99 | C35: =B35*(1-$B$5)*$B$7*$B$9*$B$10*$B$11 -> 5.1254775
A36: Jambi | B36: 90 | C36: =B36*(1-$B$5)*$B$7*$B$9*$B$10*$B$11 -> 4.659525
A37: Kalsel | B37: 46 | C37: =B37*(1-$B$5)*$B$7*$B$9*$B$10*$B$11 -> 2.381535
A38: Lainnya | B38: 196 | C38: =B38*(1-$B$5)*$B$7*$B$9*$B$10*$B$11 -> 10.14741

Sheet Keputusan PKS
A1: MODEL KEPUTUSAN PKS: apakah layanan BOO lebih murah bagi PKS daripada kolam POME? (rumus hidup)
A2: Sudut pandang PKS 45 t TBS/jam, 20 th, USD 2026 dieskalasi a_infl, diskonto biaya modal PKS. Ubah sel kuning di sini atau di Asumsi (fee, util, solar, harga listrik).
A4: Input sisi PKS | B4: Nilai | C4: Satuan | D4: Rendah / Tinggi | F4: Sumber
A5: r_mill | B5: 0.12 | C5: /th | D5: 0.1 / 0.18 | F5: Biaya modal PKS (WACC proyek nominal Indonesia 9,4-14%) [R2]
A6: p_diesel | B6: 21000 | C6: Rp/L | D6: 18200.0 / 25850.0 | F6: Solar industri diantar (HSD/B40 non-subsidi) 18.200-25.850 [R2]
A7: genset_om | B7: 0.02 | C7: USD/kWh | D7: 0.01 / 0.04 | F7: O&M genset diesel PKS (pelumas, filter, overhaul) [ASUMSI]
A8: desludge | B8: 400 | C8: juta Rp/th | D8: 200.0 / 600.0 | F8: Pengurasan lumpur kolam anaerobik ~1 kali/th, Rp 0,2-0,6 M/kejadian [R2, keyakinan rendah]
A9: pond_om | B9: 22 | C9: juta Rp/th | D9: 20.0 / 100.0 | F9: Pompa, tanggul, perawatan kolam (tanpa pengurasan) [R2]
A10: la_cost | B10: 10000 | C10: Rp/m3 | D10: 7000.0 / 19000.0 | F10: Aplikasi lahan flatbed/furrow per m3 limbah [R2]
A11: monitor | B11: 250 | C11: juta Rp/th | D11: 150.0 / 400.0 | F11: Pemantauan RKL-RPL/Persetujuan Teknis (sama untuk semua opsi) [R2]
A12: margin | B12: 15 | C12: USD/t TBS | D12: 10.0 / 25.0 | F12: Margin olah PKS per t TBS untuk menilai hari henti (penyegelan) [ASUMSI]
A13: p_enf_A | B13: 0.03 | C13: /th | D13: 0.01 / 0.06 | F13: Peluang penegakan/penyegelan per th untuk kolam terbuka (kasus PT BMB 2023, PT SIPP 2024) [ASUMSI dari R1]
A14: p_enf_D | B14: 0.005 | C14: /th | D14: 0.0 / 0.01 | F14: Peluang yang sama dengan reaktor tertutup + kolam polishing [ASUMSI]
A15: closure_d | B15: 30 | C15: hari | D15: 14.0 / 90.0 | F15: Lama henti bila disegel [ASUMSI dari R1]
A16: land_margin | B16: 32 | C16: juta Rp/ha/th | D16: 20.0 / 45.0 | F16: Margin bersih sawit per ha (TBS Rp 3.763/kg Riau Okt 2026) [R2]
... A24: desl_B | B24: 0.5 | C24: - | D24: 0.3 / 0.8 | F24: Porsi pengurasan yang tetap ada pada kolam tertutup
A26: BESARAN ANTARA
A27: TBS diolah (t/th) | B27: =t_ffb*a_util -> 270000
A28: POME (m3/th) | B28: =K_ffb*t_pome_tffb -> 234000
A29: Efluen set ke kolam polishing (m3/th) | B29: =K_pome*t_effratio -> 163179.09
A30: Listrik neto set (kWh/th) | B30: =t_E_year*a_util/t_up*a_avail*1000000 -> 6546227.3
